Workbook

Sheet Petunjuk dan Parameter
A1: Simulasi Kelayakan Usaha UMKM - Berkas Verifikasi Mankeu
A2: Periode simulasi: Februari sampai April 2026
A4: Identitas Usaha
A5: Nama usaha | B5: Dapur Sambal Nusantara
A6: Nama proyek atau siklus | B6: Siklus Produksi Februari - April 2026
A7: Sektor usaha | B7: Kuliner / F&B
A9: Parameter | B9: Nilai | C9: Satuan | D9: Keterangan
A10: Kapasitas produksi rencana | B10: 6000 | C10: botol | D10: Target keluaran satu siklus produksi tiga bulan
A11: Harga jual satuan | B11: 28000 | C11: Rp per botol | D11: Harga seragam untuk penjualan tunai maupun tempo pada simulasi ini
A12: Modal awal sendiri | B12: 15000000 | C12: Rp | D12: Setoran pemilik pada awal siklus
A13: Rencana pinjaman modal kerja | B13: 20000000 | C13: Rp | D13: Pencairan KUR modal kerja
A14: Suku bunga pinjaman | B14: 1200 | C14: bps | D14: 1.200 bps sama dengan 12,00 persen untuk satu siklus
A15: Biaya pembiayaan lainnya | B15: 400000 | C15: Rp | D15: Biaya administrasi dan provisi pinjaman
A16: Saldo kas awal | B16: 0 | C16: Rp | D16: Usaha dimulai tanpa saldo kas sebelumnya
A18: Cara memakai berkas ini
A19: 1. | B19: Buat usaha baru di Mankeu dengan sektor Kuliner / F&B, lalu buat satu proyek atau siklus.
A20: 2. | B20: Buka Berkas dan Data, pilih Ambil dari Excel, lalu pilih berkas ini.
A21: 3. | B21: Lembar RAB (Proyeksi) masuk ke buku Proyeksi; lembar Transaksi Harian (Realisasi) masuk ke buku Realisasi.
A22: 4. | B22: Isi Asumsi pada buku Proyeksi dengan nilai parameter di atas; isi Asumsi buku Realisasi hanya dengan volume dan harga jual.
A23: 5. | B23: Bandingkan angka aplikasi dengan lembar Laporan Laba Rugi dan Arus Kas dan Analisis Kelayakan.
A25: Catatan pembacaan
A26: a. | B26: Kolom Nominal (Rp) selalu berisi nilai transaksi. Kolom Pengeluaran dan Pemasukan hanya diisi untuk transaksi tunai.
A27: b. | B27: Baris Penjualan Tempo dan Belanja Tempo tidak menggerakkan kas, sehingga kolom Saldo Kas tidak berubah pada baris tersebut.
A28: c. | B28: Seluruh nilai uang adalah rupiah bulat. Tidak ada pecahan sen di berkas ini maupun di dalam aplikasi.
A30: Ringkasan hasil yang harus muncul di aplikasi
A31: Total RAB biaya (Proyeksi) | B31: 141050000
A32: Target omzet (Proyeksi) | B32: 168000000
A33: Omzet penjualan (Realisasi) | B33: 149240000
A34: Laba bersih (Realisasi) | B34: 15650000
A35: Kas akhir siklus (Realisasi) | B35: 27050000

Sheet RAB (Proyeksi)
A1: No | B1: Uraian | C1: Volume | D1: Satuan | E1: Harga Satuan (Rp) | F1: Bulan Rencana | G1: Total Anggaran (Rp)
B2: A. Peralatan Dapur dan Kafe
A3: 1 | B3: Mesin giling cabai | C3: 1 | D3: unit | E3: 4500000 | F3: 2026-02 | G3: =C3*E3 -> 4500000
A4: 2 | B4: Kompor industri dua tungku | C4: 2 | D4: unit | E4: 1750000 | F4: 2026-02 | G4: =C4*E4 -> 3500000
A5: 3 | B5: Mesin sealer botol | C5: 1 | D5: unit | E5: 2300000 | F5: 2026-02 | G5: =C5*E5 -> 2300000
A6: 4 | B6: Wajan dan panci stainless | C6: 1 | D6: set | E6: 1200000 | F6: 2026-02 | G6: =C6*E6 -> 1200000
A7: 5 | B7: Etalase dan rak simpan | C7: 1 | D7: unit | E7: 1500000 | F7: 2026-02 | G7: =C7*E7 -> 1500000
B8: B. Bahan Baku Makanan
A9: 6 | B9: Cabai rawit merah | C9: 400 | D9: kg | E9: 45000 | F9: 2026-02 | G9: =C9*E9 -> 18000000
A10: 7 | B10: Cabai rawit merah | C10: 400 | D10: kg | E10: 45000 | F10: 2026-03 | G10: =C10*E10 -> 18000000
A11: 8 | B11: Cabai rawit merah | C11: 400 | D11: kg | E11: 45000 | F11: 2026-04 | G11: =C11*E11 -> 18000000
A12: 9 | B12: Bawang merah dan bawang putih | C12: 100 | D12: kg | E12: 30000 | F12: 2026-02 | G12: =C12*E12 -> 3000000
A13: 10 | B13: Bawang merah dan bawang putih | C13: 100 | D13: kg | E13: 30000 | F13: 2026-03 | G13: =C13*E13 -> 3000000
A14: 11 | B14: Bawang merah dan bawang putih | C14: 100 | D14: kg | E14: 30000 | F14: 2026-04 | G14: =C14*E14 -> 3000000
A15: 12 | B15: Minyak goreng curah | C15: 200 | D15: liter | E15: 18000 | F15: 2026-02 | G15: =C15*E15 -> 3600000
A16: 13 | B16: Minyak goreng curah | C16: 200 | D16: liter | E16: 18000 | F16: 2026-03 | G16: =C16*E16 -> 3600000
A17: 14 | B17: Minyak goreng curah | C17: 200 | D17: liter | E17: 18000 | F17: 2026-04 | G17: =C17*E17 -> 3600000
B18: C. Bahan Minuman dan Bumbu
A19: 15 | B19: Gula, garam, dan penyedap | C19: 1 | D19: paket | E19: 2200000 | F19: 2026-02 | G19: =C19*E19 -> 2200000
A20: 16 | B20: Gula, garam, dan penyedap | C20: 1 | D20: paket | E20: 2200000 | F20: 2026-03 | G20: =C20*E20 -> 2200000
A21: 17 | B21: Gula, garam, dan penyedap | C21: 1 | D21: paket | E21: 2200000 | F21: 2026-04 | G21: =C21*E21 -> 2200000
B22: D. Kemasan dan Label
A23: 18 | B23: Botol kaca dan tutup | C23: 2000 | D23: pcs | E23: 2500 | F23: 2026-02 | G23: =C23*E23 -> 5000000
A24: 19 | B24: Botol kaca dan tutup | C24: 2000 | D24: pcs | E24: 2500 | F24: 2026-03 | G24: =C24*E24 -> 5000000
A25: 20 | B25: Botol kaca dan tutup | C25: 2000 | D25: pcs | E25: 2500 | F25: 2026-04 | G25: =C25*E25 -> 5000000
A26: 21 | B26: Label dan segel | C26: 2000 | D26: pcs | E26: 500 | F26: 2026-02 | G26: =C26*E26 -> 1000000
A27: 22 | B27: Label dan segel | C27: 2000 | D27: pcs | E27: 500 | F27: 2026-03 | G27: =C27*E27 -> 1000000
A28: 23 | B28: Label dan segel | C28: 2000 | D28: pcs | E28: 500 | F28: 2026-04 | G28: =C28*E28 -> 1000000
B29: E. Gaji Koki dan Pegawai
A30: 24 | B30: Gaji dua karyawan produksi | C30: 2 | D30: orang-bulan | E30: 2000000 | F30: 2026-02 | G30: =C30*E30 -> 4000000
A31: 25 | B31: Gaji dua karyawan produksi | C31: 2 | D31: orang-bulan | E31: 2000000 | F31: 2026-03 | G31: =C31*E31 -> 4000000
A32: 26 | B32: Gaji dua karyawan produksi | C32: 2 | D32: orang-bulan | E32: 2000000 | F32: 2026-04 | G32: =C32*E32 -> 4000000
B33: F. Sewa Tempat
A34: 27 | B34: Sewa dapur produksi | C34: 1 | D34: bulan | E34: 2500000 | F34: 2026-02 | G34: =C34*E34 -> 2500000
A35: 28 | B35: Sewa dapur produksi | C35: 1 | D35: bulan | E35: 2500000 | F35: 2026-03 | G35: =C35*E35 -> 2500000
A36: 29 | B36: Sewa dapur produksi | C36: 1 | D36: bulan | E36: 2500000 | F36: 2026-04 | G36: =C36*E36 -> 2500000
B37: G. Gas, Listrik dan Air
A38: 30 | B38: Gas, listrik, dan air dapur | C38: 1 | D38: bulan | E38: 1150000 | F38: 2026-02 | G38: =C38*E38 -> 1150000
A39: 31 | B39: Gas, listrik, dan air dapur | C39: 1 | D39: bulan | E39: 1150000 | F39: 2026-03 | G39: =C39*E39 -> 1150000
A40: 32 | B40: Gas, listrik, dan air dapur | C40: 1 | D40: bulan | E40: 1150000 | F40: 2026-04 | G40: =C40*E40 -> 1150000
...

Sheet Transaksi Harian (Realisasi)
A1: Tanggal | B1: Jenis | C1: Uraian | D1: Kategori | E1: Pihak | F1: Jatuh Tempo | G1: No. Kewajiban | H1: Volume | I1: Satuan | J1: Harga Satuan (Rp) | K1: Nominal (Rp) | L1: Pengeluaran (Rp) | M1: Pemasukan (Rp) | N1: Saldo Kas (Rp)
A2: 2026-02-01 | B2: Modal Masuk | C2: Setoran modal awal pemilik | D2: Modal Sendiri | K2: 15000000 | M2: 15000000 | N2: =0+M2-L2 -> 15000000
A3: 2026-02-02 | B3: Pinjaman Masuk | C3: Pencairan KUR modal kerja | D3: Pinjaman Usaha | K3: 20000000 | M3: 20000000 | N3: =N2+M3-L3 -> 35000000
A4: 2026-02-03 | B4: Beli Alat Tunai | C4: Mesin giling cabai | D4: Peralatan Dapur dan Kafe | H4: 1 | I4: unit | J4: 4500000 | K4: 4500000 | L4: 4500000 | N4: =N3+M4-L4 -> 30500000
A5: 2026-02-03 | B5: Beli Alat Tunai | C5: Kompor industri dua tungku | D5: Peralatan Dapur dan Kafe | H5: 2 | I5: unit | J5: 1750000 | K5: 3500000 | L5: 3500000 | N5: =N4+M5-L5 -> 27000000
A6: 2026-02-04 | B6: Beli Alat Tunai | C6: Mesin sealer botol | D6: Peralatan Dapur dan Kafe | H6: 1 | I6: unit | J6: 2300000 | K6: 2300000 | L6: 2300000 | N6: =N5+M6-L6 -> 24700000
A7: 2026-02-04 | B7: Beli Alat Tunai | C7: Wajan dan panci stainless | D7: Peralatan Dapur dan Kafe | H7: 1 | I7: set | J7: 1200000 | K7: 1200000 | L7: 1200000 | N7: =N6+M7-L7 -> 23500000
A8: 2026-02-05 | B8: Beli Alat Tunai | C8: Etalase dan rak simpan | D8: Peralatan Dapur dan Kafe | H8: 1 | I8: unit | J8: 1500000 | K8: 1500000 | L8: 1500000 | N8: =N7+M8-L8 -> 22000000
A9: 2026-02-05 | B9: Uang Keluar | C9: Sewa dapur produksi Februari | D9: Sewa Tempat | H9: 1 | I9: bulan | J9: 2500000 | K9: 2500000 | L9: 2500000 | N9: =N8+M9-L9 -> 19500000
A10: 2026-02-05 | B10: Uang Keluar | C10: Perizinan PIRT dan sertifikasi halal | D10: Perizinan dan Administrasi | H10: 1 | I10: paket | J10: 1750000 | K10: 1750000 | L10: 1750000 | N10: =N9+M10-L10 -> 17750000
A11: 2026-02-06 | B11: Uang Keluar | C11: Belanja cabai rawit merah | D11: Bahan Baku Makanan | H11: 400 | I11: kg | J11: 45000 | K11: 18000000 | L11: 18000000 | N11: =N10+M11-L11 -> -250000
A12: 2026-02-06 | B12: Uang Keluar | C12: Belanja bawang merah dan bawang putih | D12: Bahan Baku Makanan | H12: 100 | I12: kg | J12: 30000 | K12: 3000000 | L12: 3000000 | N12: =N11+M12-L12 -> -3250000
A13: 2026-02-07 | B13: Uang Keluar | C13: Minyak goreng curah | D13: Bahan Baku Makanan | H13: 200 | I13: liter | J13: 18000 | K13: 3600000 | L13: 3600000 | N13: =N12+M13-L13 -> -6850000
A14: 2026-02-07 | B14: Belanja Tempo | C14: Gula, garam, dan penyedap (tempo 30 hari) | D14: Bahan Minuman dan Bumbu | E14: Toko Sembako Jaya | F14: 2026-03-08 | G14: UT-01 | H14: 1 | I14: paket | J14: 2200000 | K14: 2200000 | N14: =N13+M14-L14 -> -6850000
A15: 2026-02-08 | B15: Uang Keluar | C15: Botol kaca dan tutup | D15: Kemasan dan Label | H15: 2000 | I15: pcs | J15: 2500 | K15: 5000000 | L15: 5000000 | N15: =N14+M15-L15 -> -11850000
A16: 2026-02-08 | B16: Uang Keluar | C16: Label dan segel | D16: Kemasan dan Label | H16: 2000 | I16: pcs | J16: 500 | K16: 1000000 | L16: 1000000 | N16: =N15+M16-L16 -> -12850000
A17: 2026-02-15 | B17: Uang Masuk | C17: Penjualan kasir 01-15 Februari | D17: Penjualan Makanan dan Minuman | H17: 520 | I17: botol | J17: 28000 | K17: 14560000 | M17: 14560000 | N17: =N16+M17-L17 -> 1710000
A18: 2026-02-20 | B18: Uang Keluar | C18: Gaji dua karyawan produksi Februari | D18: Gaji Koki dan Pegawai | H18: 2 | I18: orang-bulan | J18: 2000000 | K18: 4000000 | L18: 4000000 | N18: =N17+M18-L18 -> -2290000
A19: 2026-02-25 | B19: Uang Keluar | C19: Gas, listrik, dan air Februari | D19: Gas, Listrik dan Air | K19: 1150000 | L19: 1150000 | N19: =N18+M19-L19 -> -3440000
A20: 2026-02-26 | B20: Uang Keluar | C20: Konten promosi dan iklan media sosial | D20: Pemasaran dan Promosi | K20: 800000 | L20: 800000 | N20: =N19+M20-L20 -> -4240000
A21: 2026-02-28 | B21: Uang Masuk | C21: Penjualan kasir 16-28 Februari | D21: Penjualan Makanan dan Minuman | H21: 640 | I21: botol | J21: 28000 | K21: 17920000 | M21: 17920000 | N21: =N20+M21-L21 -> 13680000
A22: 2026-02-28 | B22: Penjualan Tempo | C22: Penjualan grosir Toko Berkah (tempo 30 hari) | D22: Penjualan Makanan dan Minuman | E22: Toko Berkah Sentosa | F22: 2026-03-30 | G22: PT-01 | H22: 250 | I22: botol | J22: 28000 | K22: 7000000 | N22: =N21+M22-L22 -> 13680000
A23: 2026-03-05 | B23: Uang Keluar | C23: Sewa dapur produksi Maret | D23: Sewa Tempat | H23: 1 | I23: bulan | J23: 2500000 | K23: 2500000 | L23: 2500000 | N23: =N22+M23-L23 -> 11180000
A24: 2026-03-08 | B24: Bayar Utang | C24: Pelunasan utang Toko Sembako Jaya | D24: Bahan Minuman dan Bumbu | E24: Toko Sembako Jaya | G24: UT-01 | K24: 2200000 | L24: 2200000 | N24: =N23+M24-L24 -> 8980000
A25: 2026-03-10 | B25: Uang Keluar | C25: Belanja cabai rawit merah | D25: Bahan Baku Makanan | H25: 420 | I25: kg | J25: 45000 | K25: 18900000 | L25: 18900000 | N25: =N24+M25-L25 -> -9920000
A26: 2026-03-10 | B26: Uang Keluar | C26: Bawang, gula, dan bumbu dapur | D26: Bahan Minuman dan Bumbu | K26: 4200000 | L26: 4200000 | N26: =N25+M26-L26 -> -14120000
A27: 2026-03-11 | B27: Uang Keluar | C27: Minyak goreng curah | D27: Bahan Baku Makanan | H27: 210 | I27: liter | J27: 18000 | K27: 3780000 | L27: 3780000 | N27: =N26+M27-L27 -> -17900000
A28: 2026-03-12 | B28: Belanja Tempo | C28: Botol kaca dan tutup (tempo 30 hari) | D28: Kemasan dan Label | E28: CV Kemasan Mitra | F28: 2026-04-11 | G28: UT-02 | H28: 2200 | I28: pcs | J28: 2500 | K28: 5500000 | N28: =N27+M28-L28 -> -17900000
A29: 2026-03-12 | B29: Uang Keluar | C29: Label dan segel | D29: Kemasan dan Label | H29: 2200 | I29: pcs | J29: 500 | K29: 1100000 | L29: 1100000 | N29: =N28+M29-L29 -> -19000000
A30: 2026-03-15 | B30: Uang Masuk | C30: Penjualan kasir 01-15 Maret | D30: Penjualan Makanan dan Minuman | H30: 760 | I30: botol | J30: 28000 | K30: 21280000 | M30: 21280000 | N30: =N29+M30-L30 -> 2280000
A31: 2026-03-20 | B31: Uang Keluar | C31: Gaji dua karyawan produksi Maret | D31: Gaji Koki dan Pegawai | H31: 2 | I31: orang-bulan | J31: 2000000 | K31: 4000000 | L31: 4000000 | N31: =N30+M31-L31 -> -1720000
A32: 2026-03-25 | B32: Uang Keluar | C32: Gas, listrik, dan air Maret | D32: Gas, Listrik dan Air | K32: 1250000 | L32: 1250000 | N32: =N31+M32-L32 -> -2970000
A33: 2026-03-26 | B33: Uang Keluar | C33: Ongkos kirim pesanan luar kota | D33: Transport dan Pengiriman | K33: 950000 | L33: 950000 | N33: =N32+M33-L33 -> -3920000
A34: 2026-03-26 | B34: Uang Keluar | C34: Iklan media sosial dan endorse | D34: Pemasaran dan Promosi | K34: 1200000 | L34: 1200000 | N34: =N33+M34-L34 -> -5120000
A35: 2026-03-28 | B35: Bayar Bunga | C35: Bunga KUR bulan Maret | D35: Biaya Bunga Pinjaman | K35: 200000 | L35: 200000 | N35: =N34+M35-L35 -> -5320000
A36: 2026-03-28 | B36: Bayar Pokok Pinjaman | C36: Angsuran pokok KUR Maret | D36: Pinjaman Usaha | K36: 1000000 | L36: 1000000 | N36: =N35+M36-L36 -> -6320000
A37: 2026-03-30 | B37: Terima Piutang | C37: Pelunasan piutang Toko Berkah Sentosa | D37: Penjualan Makanan dan Minuman | E37: Toko Berkah Sentosa | G37: PT-01 | K37: 7000000 | M37: 7000000 | N37: =N36+M37-L37 -> 680000
A38: 2026-03-31 | B38: Uang Masuk | C38: Penjualan kasir 16-31 Maret | D38: Penjualan Makanan dan Minuman | H38: 880 | I38: botol | J38: 28000 | K38: 24640000 | M38: 24640000 | N38: =N37+M38-L38 -> 25320000
A39: 2026-03-31 | B39: Penjualan Tempo | C39: Penjualan grosir Warung Bu Ani (tempo 30 hari) | D39: Penjualan Makanan dan Minuman | E39: Warung Bu Ani | F39: 2026-04-30 | G39: PT-02 | H39: 300 | I39: botol | J39: 28000 | K39: 8400000 | N39: =N38+M39-L39 -> 25320000
A40: 2026-04-02 | B40: Uang Keluar | C40: Sewa dapur produksi April | D40: Sewa Tempat | H40: 1 | I40: bulan | J40: 2500000 | K40: 2500000 | L40: 2500000 | N40: =N39+M40-L40 -> 22820000
...

Sheet Laporan Laba Rugi
A1: Laporan Laba Rugi - Realisasi Februari sampai April 2026
A2: Setiap angka pada lembar ini adalah rumus SUMIFS atas lembar Transaksi Harian (Realisasi).
A4: Uraian | B4: Jumlah (Rp) | C4: Catatan
A5: Penjualan tunai | B5: =SUMIFS('Transaksi Harian (Realisasi)'!$K$2:$K$57,'Transaksi Harian (Realisasi)'!$B$2:$B$57,"Uang Masuk") -> 133840000 | C5: Jenis Uang Masuk pada buku transaksi
A6: Penjualan tempo (piutang) | B6: =SUMIFS('Transaksi Harian (Realisasi)'!$K$2:$K$57,'Transaksi Harian (Realisasi)'!$B$2:$B$57,"Penjualan Tempo") -> 15400000 | C6: Diakui sebagai omzet saat penyerahan barang, bukan saat uang diterima
A7: Omzet penjualan | B7: =B5+B6 -> 149240000
A9: Beban pokok penjualan (HPP akuntansi)
A10: Bahan Baku Makanan | B10: =SUMIFS('Transaksi Harian (Realisasi)'!$K$2:$K$57,'Transaksi Harian (Realisasi)'!$D$2:$D$57,"Bahan Baku Makanan",'Transaksi Harian (Realisasi)'!$B$2:$B$57,"Uang Keluar")+SUMIFS('Transaksi Harian (Realisasi)'!$K$2:$K$57,'Transaksi Harian (Realisasi)'!$D$2:$D$57,"Bahan Baku Makanan",'Transaksi Harian (Realisasi)'!$B$2:$B$57,"Belanja Tempo") -> 71580000
A11: Bahan Minuman dan Bumbu | B11: =SUMIFS('Transaksi Harian (Realisasi)'!$K$2:$K$57,'Transaksi Harian (Realisasi)'!$D$2:$D$57,"Bahan Minuman dan Bumbu",'Transaksi Harian (Realisasi)'!$B$2:$B$57,"Uang Keluar")+SUMIFS('Transaksi Harian (Realisasi)'!$K$2:$K$57,'Transaksi Harian (Realisasi)'!$D$2:$D$57,"Bahan Minuman dan Bumbu",'Transaksi Harian (Realisasi)'!$B$2:$B$57,"Belanja Tempo") -> 10900000
A12: Kemasan dan Label | B12: =SUMIFS('Transaksi Harian (Realisasi)'!$K$2:$K$57,'Transaksi Harian (Realisasi)'!$D$2:$D$57,"Kemasan dan Label",'Transaksi Harian (Realisasi)'!$B$2:$B$57,"Uang Keluar")+SUMIFS('Transaksi Harian (Realisasi)'!$K$2:$K$57,'Transaksi Harian (Realisasi)'!$D$2:$D$57,"Kemasan dan Label",'Transaksi Harian (Realisasi)'!$B$2:$B$57,"Belanja Tempo") -> 19800000
A13: Gaji Koki dan Pegawai | B13: =SUMIFS('Transaksi Harian (Realisasi)'!$K$2:$K$57,'Transaksi Harian (Realisasi)'!$D$2:$D$57,"Gaji Koki dan Pegawai",'Transaksi Harian (Realisasi)'!$B$2:$B$57,"Uang Keluar")+SUMIFS('Transaksi Harian (Realisasi)'!$K$2:$K$57,'Transaksi Harian (Realisasi)'!$D$2:$D$57,"Gaji Koki dan Pegawai",'Transaksi Harian (Realisasi)'!$B$2:$B$57,"Belanja Tempo") -> 12400000
A14: Total beban pokok penjualan | B14: =B10+B11+B12+B13 -> 114680000
A15: Laba kotor | B15: =B7-B14 -> 34560000 | C15: Omzet penjualan dikurangi beban pokok penjualan
A17: Beban operasional
A18: Sewa Tempat | B18: =SUMIFS('Transaksi Harian (Realisasi)'!$K$2:$K$57,'Transaksi Harian (Realisasi)'!$D$2:$D$57,"Sewa Tempat",'Transaksi Harian (Realisasi)'!$B$2:$B$57,"Uang Keluar")+SUMIFS('Transaksi Harian (Realisasi)'!$K$2:$K$57,'Transaksi Harian (Realisasi)'!$D$2:$D$57,"Sewa Tempat",'Transaksi Harian (Realisasi)'!$B$2:$B$57,"Belanja Tempo") -> 7500000
A19: Gas, Listrik dan Air | B19: =SUMIFS('Transaksi Harian (Realisasi)'!$K$2:$K$57,'Transaksi Harian (Realisasi)'!$D$2:$D$57,"Gas, Listrik dan Air",'Transaksi Harian (Realisasi)'!$B$2:$B$57,"Uang Keluar")+SUMIFS('Transaksi Harian (Realisasi)'!$K$2:$K$57,'Transaksi Harian (Realisasi)'!$D$2:$D$57,"Gas, Listrik dan Air",'Transaksi Harian (Realisasi)'!$B$2:$B$57,"Belanja Tempo") -> 3720000
A20: Perizinan dan Administrasi | B20: =SUMIFS('Transaksi Harian (Realisasi)'!$K$2:$K$57,'Transaksi Harian (Realisasi)'!$D$2:$D$57,"Perizinan dan Administrasi",'Transaksi Harian (Realisasi)'!$B$2:$B$57,"Uang Keluar")+SUMIFS('Transaksi Harian (Realisasi)'!$K$2:$K$57,'Transaksi Harian (Realisasi)'!$D$2:$D$57,"Perizinan dan Administrasi",'Transaksi Harian (Realisasi)'!$B$2:$B$57,"Belanja Tempo") -> 1750000
A21: Pemasaran dan Promosi | B21: =SUMIFS('Transaksi Harian (Realisasi)'!$K$2:$K$57,'Transaksi Harian (Realisasi)'!$D$2:$D$57,"Pemasaran dan Promosi",'Transaksi Harian (Realisasi)'!$B$2:$B$57,"Uang Keluar")+SUMIFS('Transaksi Harian (Realisasi)'!$K$2:$K$57,'Transaksi Harian (Realisasi)'!$D$2:$D$57,"Pemasaran dan Promosi",'Transaksi Harian (Realisasi)'!$B$2:$B$57,"Belanja Tempo") -> 3500000
A22: Transport dan Pengiriman | B22: =SUMIFS('Transaksi Harian (Realisasi)'!$K$2:$K$57,'Transaksi Harian (Realisasi)'!$D$2:$D$57,"Transport dan Pengiriman",'Transaksi Harian (Realisasi)'!$B$2:$B$57,"Uang Keluar")+SUMIFS('Transaksi Harian (Realisasi)'!$K$2:$K$57,'Transaksi Harian (Realisasi)'!$D$2:$D$57,"Transport dan Pengiriman",'Transaksi Harian (Realisasi)'!$B$2:$B$57,"Belanja Tempo") -> 2050000
A23: Total beban operasional | B23: =B18+B19+B20+B21+B22 -> 18520000
A24: Laba usaha | B24: =B15-B23 -> 16040000 | C24: Laba sebelum beban bunga
A26: Beban bunga pinjaman | B26: =SUMIFS('Transaksi Harian (Realisasi)'!$K$2:$K$57,'Transaksi Harian (Realisasi)'!$B$2:$B$57,"Bayar Bunga") -> 390000 | C26: Bunga adalah beban; angsuran pokok bukan beban
A27: Laba bersih | B27: =B24-B26 -> 15650000 | C27: Angka ini harus sama dengan Laba Bersih pada Laporan Mankeu
A29: Pemeriksaan silang dengan model Mankeu
A30: Total beban operasional versi Mankeu | B30: =B14+B23+B26 -> 133590000 | C30: Mankeu menggabungkan HPP, beban operasional, dan bunga menjadi satu Beban Operasional
A31: Laba bersih versi Mankeu | B31: =B7-(B14+B23+B26) -> 15650000 | C31: Sama dengan Laba bersih di atas
A32: Margin laba bersih (persen) | B32: =ROUND(B27/B7*100,2) -> 10.49 | C32: Dibulatkan dua angka di belakang koma, sama dengan aplikasi

Sheet Arus Kas dan Analisis Kelayakan
A1: Arus Kas dan Analisis Kelayakan Usaha
A2: Bagian A dan B memakai buku Realisasi. Bagian C memakai buku Proyeksi (RAB dan parameter).
A4: A. Arus kas bulanan (Realisasi)
A5: Bulan | B5: Arus Kas Operasi (Rp) | C5: Arus Kas Investasi (Rp) | D5: Arus Kas Pendanaan (Rp) | E5: Arus Kas Bersih (Rp) | F5: Kas Kumulatif (Rp)
A6: Februari 2026 | B6: =SUMIFS('Transaksi Harian (Realisasi)'!$K$2:$K$57,'Transaksi Harian (Realisasi)'!$B$2:$B$57,"Uang Masuk",'Transaksi Harian (Realisasi)'!$A$2:$A$57,">=2026-02-01",'Transaksi Harian (Realisasi)'!$A$2:$A$57,"<=2026-02-31")+SUMIFS('Transaksi Harian (Realisasi)'!$K$2:$K$57,'Transaksi Harian (Realisasi)'!$B$2:$B$57,"Terima Piutang",'Transaksi Harian (Realisasi)'!$A$2:$A$57,">=2026-02-01",'Transaksi Harian (Realisasi)'!$A$2:$A$57,"<=2026-02-31")-(SUMIFS('Transaksi Harian (Realisasi)'!$K$2:$K$57,'Transaksi Harian (Realisasi)'!$B$2:$B$57,"Uang Keluar",'Transaksi Harian (Realisasi)'!$A$2:$A$57,">=2026-02-01",'Transaksi Harian (Realisasi)'!$A$2:$A$57,"<=2026-02-31")+SUMIFS('Transaksi Harian (Realisasi)'!$K$2:$K$57,'Transaksi Harian (Realisasi)'!$B$2:$B$57,"Bayar Utang",'Transaksi Harian (Realisasi)'!$A$2:$A$57,">=2026-02-01",'Transaksi Harian (Realisasi)'!$A$2:$A$57,"<=2026-02-31")+SUMIFS('Transaksi Harian (Realisasi)'!$K$2:$K$57,'Transaksi Harian (Realisasi)'!$B$2:$B$57,"Bayar Bunga",'Transaksi Harian (Realisasi)'!$A$2:$A$57,">=2026-02-01",'Transaksi Harian (Realisasi)'!$A$2:$A$57,"<=2026-02-31")) -> -8320000 | C6: =-(SUMIFS('Transaksi Harian (Realisasi)'!$K$2:$K$57,'Transaksi Harian (Realisasi)'!$B$2:$B$57,"Beli Alat Tunai",'Transaksi Harian (Realisasi)'!$A$2:$A$57,">=2026-02-01",'Transaksi Harian (Realisasi)'!$A$2:$A$57,"<=2026-02-31")) -> -13000000 | D6: =SUMIFS('Transaksi Harian (Realisasi)'!$K$2:$K$57,'Transaksi Harian (Realisasi)'!$B$2:$B$57,"Modal Masuk",'Transaksi Harian (Realisasi)'!$A$2:$A$57,">=2026-02-01",'Transaksi Harian (Realisasi)'!$A$2:$A$57,"<=2026-02-31")+SUMIFS('Transaksi Harian (Realisasi)'!$K$2:$K$57,'Transaksi Harian (Realisasi)'!$B$2:$B$57,"Pinjaman Masuk",'Transaksi Harian (Realisasi)'!$A$2:$A$57,">=2026-02-01",'Transaksi Harian (Realisasi)'!$A$2:$A$57,"<=2026-02-31")-(SUMIFS('Transaksi Harian (Realisasi)'!$K$2:$K$57,'Transaksi Harian (Realisasi)'!$B$2:$B$57,"Modal Keluar",'Transaksi Harian (Realisasi)'!$A$2:$A$57,">=2026-02-01",'Transaksi Harian (Realisasi)'!$A$2:$A$57,"<=2026-02-31")+SUMIFS('Transaksi Harian (Realisasi)'!$K$2:$K$57,'Transaksi Harian (Realisasi)'!$B$2:$B$57,"Bayar Pokok Pinjaman",'Transaksi Harian (Realisasi)'!$A$2:$A$57,">=2026-02-01",'Transaksi Harian (Realisasi)'!$A$2:$A$57,"<=2026-02-31")) -> 35000000 | E6: =B6+C6+D6 -> 13680000 | F6: =0+E6 -> 13680000
A7: Maret 2026 | B7: =SUMIFS('Transaksi Harian (Realisasi)'!$K$2:$K$57,'Transaksi Harian (Realisasi)'!$B$2:$B$57,"Uang Masuk",'Transaksi Harian (Realisasi)'!$A$2:$A$57,">=2026-03-01",'Transaksi Harian (Realisasi)'!$A$2:$A$57,"<=2026-03-31")+SUMIFS('Transaksi Harian (Realisasi)'!$K$2:$K$57,'Transaksi Harian (Realisasi)'!$B$2:$B$57,"Terima Piutang",'Transaksi Harian (Realisasi)'!$A$2:$A$57,">=2026-03-01",'Transaksi Harian (Realisasi)'!$A$2:$A$57,"<=2026-03-31")-(SUMIFS('Transaksi Harian (Realisasi)'!$K$2:$K$57,'Transaksi Harian (Realisasi)'!$B$2:$B$57,"Uang Keluar",'Transaksi Harian (Realisasi)'!$A$2:$A$57,">=2026-03-01",'Transaksi Harian (Realisasi)'!$A$2:$A$57,"<=2026-03-31")+SUMIFS('Transaksi Harian (Realisasi)'!$K$2:$K$57,'Transaksi Harian (Realisasi)'!$B$2:$B$57,"Bayar Utang",'Transaksi Harian (Realisasi)'!$A$2:$A$57,">=2026-03-01",'Transaksi Harian (Realisasi)'!$A$2:$A$57,"<=2026-03-31")+SUMIFS('Transaksi Harian (Realisasi)'!$K$2:$K$57,'Transaksi Harian (Realisasi)'!$B$2:$B$57,"Bayar Bunga",'Transaksi Harian (Realisasi)'!$A$2:$A$57,">=2026-03-01",'Transaksi Harian (Realisasi)'!$A$2:$A$57,"<=2026-03-31")) -> 12640000 | C7: =-(SUMIFS('Transaksi Harian (Realisasi)'!$K$2:$K$57,'Transaksi Harian (Realisasi)'!$B$2:$B$57,"Beli Alat Tunai",'Transaksi Harian (Realisasi)'!$A$2:$A$57,">=2026-03-01",'Transaksi Harian (Realisasi)'!$A$2:$A$57,"<=2026-03-31")) -> 0 | D7: =SUMIFS('Transaksi Harian (Realisasi)'!$K$2:$K$57,'Transaksi Harian (Realisasi)'!$B$2:$B$57,"Modal Masuk",'Transaksi Harian (Realisasi)'!$A$2:$A$57,">=2026-03-01",'Transaksi Harian (Realisasi)'!$A$2:$A$57,"<=2026-03-31")+SUMIFS('Transaksi Harian (Realisasi)'!$K$2:$K$57,'Transaksi Harian (Realisasi)'!$B$2:$B$57,"Pinjaman Masuk",'Transaksi Harian (Realisasi)'!$A$2:$A$57,">=2026-03-01",'Transaksi Harian (Realisasi)'!$A$2:$A$57,"<=2026-03-31")-(SUMIFS('Transaksi Harian (Realisasi)'!$K$2:$K$57,'Transaksi Harian (Realisasi)'!$B$2:$B$57,"Modal Keluar",'Transaksi Harian (Realisasi)'!$A$2:$A$57,">=2026-03-01",'Transaksi Harian (Realisasi)'!$A$2:$A$57,"<=2026-03-31")+SUMIFS('Transaksi Harian (Realisasi)'!$K$2:$K$57,'Transaksi Harian (Realisasi)'!$B$2:$B$57,"Bayar Pokok Pinjaman",'Transaksi Harian (Realisasi)'!$A$2:$A$57,">=2026-03-01",'Transaksi Harian (Realisasi)'!$A$2:$A$57,"<=2026-03-31")) -> -1000000 | E7: =B7+C7+D7 -> 11640000 | F7: =F6+E7 -> 25320000
A8: April 2026 | B8: =SUMIFS('Transaksi Harian (Realisasi)'!$K$2:$K$57,'Transaksi Harian (Realisasi)'!$B$2:$B$57,"Uang Masuk",'Transaksi Harian (Realisasi)'!$A$2:$A$57,">=2026-04-01",'Transaksi Harian (Realisasi)'!$A$2:$A$57,"<=2026-04-31")+SUMIFS('Transaksi Harian (Realisasi)'!$K$2:$K$57,'Transaksi Harian (Realisasi)'!$B$2:$B$57,"Terima Piutang",'Transaksi Harian (Realisasi)'!$A$2:$A$57,">=2026-04-01",'Transaksi Harian (Realisasi)'!$A$2:$A$57,"<=2026-04-31")-(SUMIFS('Transaksi Harian (Realisasi)'!$K$2:$K$57,'Transaksi Harian (Realisasi)'!$B$2:$B$57,"Uang Keluar",'Transaksi Harian (Realisasi)'!$A$2:$A$57,">=2026-04-01",'Transaksi Harian (Realisasi)'!$A$2:$A$57,"<=2026-04-31")+SUMIFS('Transaksi Harian (Realisasi)'!$K$2:$K$57,'Transaksi Harian (Realisasi)'!$B$2:$B$57,"Bayar Utang",'Transaksi Harian (Realisasi)'!$A$2:$A$57,">=2026-04-01",'Transaksi Harian (Realisasi)'!$A$2:$A$57,"<=2026-04-31")+SUMIFS('Transaksi Harian (Realisasi)'!$K$2:$K$57,'Transaksi Harian (Realisasi)'!$B$2:$B$57,"Bayar Bunga",'Transaksi Harian (Realisasi)'!$A$2:$A$57,">=2026-04-01",'Transaksi Harian (Realisasi)'!$A$2:$A$57,"<=2026-04-31")) -> 7930000 | C8: =-(SUMIFS('Transaksi Harian (Realisasi)'!$K$2:$K$57,'Transaksi Harian (Realisasi)'!$B$2:$B$57,"Beli Alat Tunai",'Transaksi Harian (Realisasi)'!$A$2:$A$57,">=2026-04-01",'Transaksi Harian (Realisasi)'!$A$2:$A$57,"<=2026-04-31")) -> -3200000 | D8: =SUMIFS('Transaksi Harian (Realisasi)'!$K$2:$K$57,'Transaksi Harian (Realisasi)'!$B$2:$B$57,"Modal Masuk",'Transaksi Harian (Realisasi)'!$A$2:$A$57,">=2026-04-01",'Transaksi Harian (Realisasi)'!$A$2:$A$57,"<=2026-04-31")+SUMIFS('Transaksi Harian (Realisasi)'!$K$2:$K$57,'Transaksi Harian (Realisasi)'!$B$2:$B$57,"Pinjaman Masuk",'Transaksi Harian (Realisasi)'!$A$2:$A$57,">=2026-04-01",'Transaksi Harian (Realisasi)'!$A$2:$A$57,"<=2026-04-31")-(SUMIFS('Transaksi Harian (Realisasi)'!$K$2:$K$57,'Transaksi Harian (Realisasi)'!$B$2:$B$57,"Modal Keluar",'Transaksi Harian (Realisasi)'!$A$2:$A$57,">=2026-04-01",'Transaksi Harian (Realisasi)'!$A$2:$A$57,"<=2026-04-31")+SUMIFS('Transaksi Harian (Realisasi)'!$K$2:$K$57,'Transaksi Harian (Realisasi)'!$B$2:$B$57,"Bayar Pokok Pinjaman",'Transaksi Harian (Realisasi)'!$A$2:$A$57,">=2026-04-01",'Transaksi Harian (Realisasi)'!$A$2:$A$57,"<=2026-04-31")) -> -3000000 | E8: =B8+C8+D8 -> 1730000 | F8: =F7+E8 -> 27050000
A9: Total siklus | B9: =SUM(B6:B8) -> 12250000 | C9: =SUM(C6:C8) -> -16200000 | D9: =SUM(D6:D8) -> 31000000 | E9: =SUM(E6:E8) -> 27050000 | F9: =F8 -> 27050000
A11: B. Kebutuhan modal kerja (Realisasi)
A12: Kas sebelum pendanaan (operasi ditambah investasi) | B12: =B9+C9 -> -3950000 | C12: Saldo kas awal ditambah arus kas operasi dan investasi
A13: Defisit kumulatif terdalam | B13: 0 | C13: Nilai negatif terdalam pada kolom Kas Kumulatif; nol bila tidak pernah negatif
A14: Kebutuhan modal kerja (financing gap) | B14: =MAX(-B12,B13,0) -> 3950000 | C14: Sama dengan Kebutuhan Modal Kerja pada Laporan Mankeu
A15: Piutang belum tertagih | B15: 3400000 | C15: Sisa tagihan Warung Bu Ani
A16: Utang belum dibayar | B16: 0 | C16: Seluruh utang dagang sudah dilunasi
A18: C. Analisis kelayakan - buku Proyeksi
A19: Komponen | B19: Nilai | C19: Cara hitung
A20: Total anggaran biaya operasional | B20: 128050000 | C20: Seluruh baris RAB selain peralatan dan target omzet
A21: Beban bunga pinjaman | B21: 2400000 | C21: Pinjaman dikali suku bunga dibagi 10.000 basis poin
A22: Biaya pembiayaan lainnya | B22: 400000 | C22: Parameter
A23: Total biaya produksi | B23: =B20+B21+B22 -> 130850000 | C23: Dasar HPP, BEP, dan BCR di aplikasi
A24: Estimasi omzet | B24: 168000000 | C24: 6000 botol dikali harga jual satuan
A25: HPP (biaya total per botol) | B25: =ROUND(B23/6000,0) -> 21808 | C25: Istilah HPP di aplikasi berarti biaya total per satuan, bukan hanya beban pokok penjualan
A26: BEP produksi (titik impas) | B26: =ROUND(B23/28000,3) -> 4673.214 | C26: Total biaya dibagi harga jual, dalam botol
A27: BEP penjualan (omzet impas) | B27: =B23 -> 130850000 | C27: Sama dengan total biaya produksi
A28: Laba bersih rencana | B28: =B24-B23 -> 37150000
A29: Margin laba bersih (persen) | B29: =ROUND(B28/B24*100,2) -> 22.11
A30: B/C Ratio | B30: =ROUND(B24/B23,3) -> 1.284 | C30: Layak bila lebih besar atau sama dengan 1,000
A31: Status kelayakan | B31: LAYAK
A33: C2. Jadwal kas rencana dan kebutuhan modal kerja
A34: Bulan | B34: Arus Kas Operasi (Rp) | C34: Arus Kas Investasi (Rp) | D34: Arus Kas Bersih (Rp) | E34: Kas Kumulatif (Rp)
A35: Februari 2026 | B35: -1850000 | C35: -13000000 | D35: =B35+C35 -> -14850000 | E35: =0+D35 -> -14850000
A36: Maret 2026 | B36: 13900000 | C36: 0 | D36: =B36+C36 -> 13900000 | E36: =E35+D36 -> -950000
A37: April 2026 | B37: 27900000 | C37: 0 | D37: =B37+C37 -> 27900000 | E37: =E36+D37 -> 26950000
A38: Titik terendah kas kumulatif | B38: =MIN(E35:E37) -> -14850000 | E38: Bulan pertama menanggung seluruh peralatan dan stok sebelum penjualan naik
A39: Kebutuhan modal kerja rencana | B39: =MAX(-MIN(E35:E37),0) -> 14850000 | E39: Ditutup oleh modal sendiri dan pinjaman pada parameter
A41: D. Analisis kelayakan - buku Realisasi
A42: Komponen | B42: Nilai | C42: Cara hitung
A43: Total biaya produksi | B43: 133590000 | C43: Beban operasional Mankeu, sudah termasuk bunga
A44: Omzet penjualan | B44: 149240000 | C44: 5330 botol terjual dikali harga jual satuan
A45: HPP (biaya total per botol) | B45: =ROUND(B43/5330,0) -> 25064
...
